<?xml version="1.0" ?>
<!-- =================================================================================== -->
<!-- |    This document was autogenerated by xacro from ur3_2_robots.urdf.xacro        | -->
<!-- |    EDITING THIS FILE BY HAND IS NOT RECOMMENDED                                 | -->
<!-- =================================================================================== -->
<robot name="ur3">
  <gazebo>
    <plugin filename="libgazebo_ros_control.so" name="ros_control">
      <!--robotNamespace>/</robotNamespace-->
      <!--robotSimType>gazebo_ros_control/DefaultRobotHWSim</robotSimType-->
    </plugin>
    <!--
    <plugin name="gazebo_ros_power_monitor_controller" filename="libgazebo_ros_power_monitor.so">
      <alwaysOn>true</alwaysOn>
      <updateRate>1.0</updateRate>
      <timeout>5</timeout>
      <powerStateTopic>power_state</powerStateTopic>
      <powerStateRate>10.0</powerStateRate>
      <fullChargeCapacity>87.78</fullChargeCapacity>     
      <dischargeRate>-474</dischargeRate>
      <chargeRate>525</chargeRate>
      <dischargeVoltage>15.52</dischargeVoltage>
      <chargeVoltage>16.41</chargeVoltage>
    </plugin>
-->
  </gazebo>
  <!--
  Author: Felix Messmer
-->
  <!--
  Author: Ignacio Fidalgo
-->
  <!-- measured from model -->
  <link name="robot_1_base_link">
    <visual>
      <origin rpy="0 0 3.141592653589793" xyz="0 0 0"/>
      <geometry>
        <mesh filename="package://ur_description/meshes/ur3/visual/base.dae"/>
      </geometry>
      <material name="LightGrey">
        <color rgba="0.7 0.7 0.7 1.0"/>
      </material>
    </visual>
    <collision>
      <origin rpy="0 0 3.141592653589793" xyz="0 0 0"/>
      <geometry>
        <mesh filename="package://ur_description/meshes/ur3/collision/base.stl"/>
      </geometry>
    </collision>
    <inertial>
      <mass value="2.0"/>
      <origin rpy="0 0 0" xyz="0.0 0.0 0.0"/>
      <inertia ixx="0.0030531654454" ixy="0.0" ixz="0.0" iyy="0.0030531654454" iyz="0.0" izz="0.005625"/>
    </inertial>
  </link>
  <joint name="robot_1_shoulder_pan_joint" type="revolute">
    <parent link="robot_1_base_link"/>
    <child link="robot_1_shoulder_link"/>
    <origin rpy="0 0 3.141592528371097" xyz="0 0 0.151982148052407"/>
    <axis xyz="0 0 1"/>
    <limit effort="330.0" lower="-3.141592653589793" upper="3.141592653589793" velocity="2.16"/>
    <dynamics damping="0.0" friction="0.0"/>
  </joint>
  <link name="robot_1_shoulder_link">
    <visual>
      <origin rpy="0 0 3.141592653589793" xyz="0 0 0"/>
      <geometry>
        <mesh filename="package://ur_description/meshes/ur3/visual/shoulder.dae"/>
      </geometry>
      <material name="LightGrey">
        <color rgba="0.7 0.7 0.7 1.0"/>
      </material>
    </visual>
    <collision>
      <origin rpy="0 0 3.141592653589793" xyz="0 0 0"/>
      <geometry>
        <mesh filename="package://ur_description/meshes/ur3/collision/shoulder.stl"/>
      </geometry>
    </collision>
    <inertial>
      <mass value="2.0"/>
      <origin rpy="0 0 0" xyz="0.0 0.0 0.0"/>
      <inertia ixx="0.008093163429399999" ixy="0.0" ixz="0.0" iyy="0.008093163429399999" iyz="0.0" izz="0.005625"/>
    </inertial>
  </link>
  <joint name="robot_1_shoulder_lift_joint" type="revolute">
    <parent link="robot_1_shoulder_link"/>
    <child link="robot_1_upper_arm_link"/>
    <origin rpy="1.570529532239682 0 6.651065255205953e-06" xyz="-0.000117751414108642 0 0"/>
    <axis xyz="0 0 1"/>
    <limit effort="330.0" lower="-3.141592653589793" upper="3.141592653589793" velocity="2.16"/>
    <dynamics damping="0.0" friction="0.0"/>
  </joint>
  <link name="robot_1_upper_arm_link">
    <visual>
      <origin rpy="1.5707963267948966 0 -1.5707963267948966" xyz="0 0 0.1198"/>
      <geometry>
        <mesh filename="package://ur_description/meshes/ur3/visual/upperarm.dae"/>
      </geometry>
      <material name="LightGrey">
        <color rgba="0.7 0.7 0.7 1.0"/>
      </material>
    </visual>
    <collision>
      <origin rpy="1.5707963267948966 0 -1.5707963267948966" xyz="0 0 0.1198"/>
      <geometry>
        <mesh filename="package://ur_description/meshes/ur3/collision/upperarm.stl"/>
      </geometry>
    </collision>
    <inertial>
      <mass value="3.42"/>
      <origin rpy="0 1.5707963267948966 0" xyz="-0.12191505529225105 0.0 0.12"/>
      <inertia ixx="0.021753506304474392" ixy="0.0" ixz="0.0" iyy="0.021753506304474392" iyz="0.0" izz="0.00961875"/>
    </inertial>
  </link>
  <joint name="robot_1_elbow_joint" type="revolute">
    <parent link="robot_1_upper_arm_link"/>
    <child link="robot_1_forearm_link"/>
    <origin rpy="3.140422330317566 3.140175127557685 3.141557960492696" xyz="-0.2438301105845021 0 0"/>
    <axis xyz="0 0 1"/>
    <limit effort="150.0" lower="-3.141592653589793" upper="3.141592653589793" velocity="3.15"/>
    <dynamics damping="0.0" friction="0.0"/>
  </joint>
  <link name="robot_1_forearm_link">
    <visual>
      <origin rpy="1.5707963267948966 0 -1.5707963267948966" xyz="0 0 0.0275"/>
      <geometry>
        <mesh filename="package://ur_description/meshes/ur3/visual/forearm.dae"/>
      </geometry>
      <material name="LightGrey">
        <color rgba="0.7 0.7 0.7 1.0"/>
      </material>
    </visual>
    <collision>
      <origin rpy="1.5707963267948966 0 -1.5707963267948966" xyz="0 0 0.0275"/>
      <geometry>
        <mesh filename="package://ur_description/meshes/ur3/collision/forearm.stl"/>
      </geometry>
    </collision>
    <inertial>
      <mass value="1.26"/>
      <origin rpy="0 1.5707963267948966 0" xyz="-0.12191505529225105 0.0 0.0275"/>
      <inertia ixx="0.006536231541073107" ixy="0.0" ixz="0.0" iyy="0.006536231541073107" iyz="0.0" izz="0.00354375"/>
    </inertial>
  </link>
  <joint name="robot_1_wrist_1_joint" type="revolute">
    <parent link="robot_1_forearm_link"/>
    <child link="robot_1_wrist_1_link"/>
    <origin rpy="0.006363349347924476 0.00401697960892016 4.539196023121239e-06" xyz="-0.2130137298406746 -0.0008374574461011085 0.131604615239527"/>
    <axis xyz="0 0 1"/>
    <limit effort="54.0" lower="-3.141592653589793" upper="3.141592653589793" velocity="3.2"/>
    <dynamics damping="0.0" friction="0.0"/>
  </joint>
  <link name="robot_1_wrist_1_link">
    <visual>
      <origin rpy="1.5707963267948966 0 0" xyz="0 0 -0.085"/>
      <geometry>
        <mesh filename="package://ur_description/meshes/ur3/visual/wrist1.dae"/>
      </geometry>
      <material name="LightGrey">
        <color rgba="0.7 0.7 0.7 1.0"/>
      </material>
    </visual>
    <collision>
      <origin rpy="1.5707963267948966 0 0" xyz="0 0 -0.085"/>
      <geometry>
        <mesh filename="package://ur_description/meshes/ur3/collision/wrist1.stl"/>
      </geometry>
    </collision>
    <inertial>
      <mass value="0.8"/>
      <origin rpy="0 0 0" xyz="0.0 0.0 0.0"/>
      <inertia ixx="0.0016115361059691796" ixy="0.0" ixz="0.0" iyy="0.0016115361059691796" iyz="0.0" izz="0.00225"/>
    </inertial>
  </link>
  <joint name="robot_1_wrist_2_joint" type="revolute">
    <parent link="robot_1_wrist_1_link"/>
    <child link="robot_1_wrist_2_link"/>
    <origin rpy="1.571802682556826 0 -2.655106245398608e-06" xyz="6.007850950088259e-06 -0.08542863254646067 -8.597162561949335e-05"/>
    <axis xyz="0 0 1"/>
    <limit effort="54.0" lower="-3.141592653589793" upper="3.141592653589793" velocity="3.2"/>
    <dynamics damping="0.0" friction="0.0"/>
  </joint>
  <link name="robot_1_wrist_2_link">
    <visual>
      <origin rpy="0 0 0" xyz="0 0 -0.085"/>
      <geometry>
        <mesh filename="package://ur_description/meshes/ur3/visual/wrist2.dae"/>
      </geometry>
      <material name="LightGrey">
        <color rgba="0.7 0.7 0.7 1.0"/>
      </material>
    </visual>
    <collision>
      <origin rpy="0 0 0" xyz="0 0 -0.085"/>
      <geometry>
        <mesh filename="package://ur_description/meshes/ur3/collision/wrist2.stl"/>
      </geometry>
    </collision>
    <inertial>
      <mass value="0.8"/>
      <origin rpy="0 0 0" xyz="0.0 0.0 0.0"/>
      <inertia ixx="0.001691598927723632" ixy="0.0" ixz="0.0" iyy="0.001691598927723632" iyz="0.0" izz="0.00225"/>
    </inertial>
  </link>
  <joint name="robot_1_wrist_3_joint" type="revolute">
    <parent link="robot_1_wrist_2_link"/>
    <child link="robot_1_wrist_3_link"/>
    <origin rpy="1.570313920297103 3.141592653589793 3.141592540005369" xyz="-5.693288443582482e-05 0.09218998896546257 -4.447305315826958e-05"/>
    <axis xyz="0 0 1"/>
    <limit effort="54.0" lower="-3.141592653589793" upper="3.141592653589793" velocity="3.2"/>
    <dynamics damping="0.0" friction="0.0"/>
  </joint>
  <link name="robot_1_wrist_3_link">
    <visual>
      <origin rpy="1.5707963267948966 0 0" xyz="0 0 -0.082"/>
      <geometry>
        <mesh filename="package://ur_description/meshes/ur3/visual/wrist3.dae"/>
      </geometry>
      <material name="LightGrey">
        <color rgba="0.7 0.7 0.7 1.0"/>
      </material>
    </visual>
    <collision>
      <origin rpy="1.5707963267948966 0 0" xyz="0 0 -0.082"/>
      <geometry>
        <mesh filename="package://ur_description/meshes/ur3/collision/wrist3.stl"/>
      </geometry>
    </collision>
    <inertial>
      <mass value="0.35"/>
      <origin rpy="0 0 0" xyz="0.0 0.0 -0.01525"/>
      <inertia ixx="0.00020431970993874997" ixy="0.0" ixz="0.0" iyy="0.00020431970993874997" iyz="0.0" izz="0.000354375"/>
    </inertial>
  </link>
  <joint name="robot_1_ee_fixed_joint" type="fixed">
    <parent link="robot_1_wrist_3_link"/>
    <child link="robot_1_ee_link"/>
    <origin rpy="0.0 -1.5707963267948966 1.5707963267948966" xyz="0.0 0.0 0.0"/>
  </joint>
  <link name="robot_1_ee_link">
    <collision>
      <geometry>
        <box size="0.01 0.01 0.01"/>
      </geometry>
      <origin rpy="0 0 0" xyz="-0.01 0 0"/>
    </collision>
  </link>
  <joint name="robot_1_wrist_3_passive_joint" type="fixed">
    <origin rpy="0 0 0" xyz="0 0 0"/>
    <parent link="robot_1_wrist_3_link"/>
    <child link="robot_1_tool0"/>
  </joint>
  <transmission name="robot_1_shoulder_pan_trans">
    <type>transmission_interface/SimpleTransmission</type>
    <joint name="robot_1_shoulder_pan_joint">
      <hardwareInterface>hardware_interface/PositionJointInterface</hardwareInterface>
    </joint>
    <actuator name="robot_1_shoulder_pan_motor">
      <mechanicalReduction>1</mechanicalReduction>
    </actuator>
  </transmission>
  <transmission name="robot_1_shoulder_lift_trans">
    <type>transmission_interface/SimpleTransmission</type>
    <joint name="robot_1_shoulder_lift_joint">
      <hardwareInterface>hardware_interface/PositionJointInterface</hardwareInterface>
    </joint>
    <actuator name="robot_1_shoulder_lift_motor">
      <mechanicalReduction>1</mechanicalReduction>
    </actuator>
  </transmission>
  <transmission name="robot_1_elbow_trans">
    <type>transmission_interface/SimpleTransmission</type>
    <joint name="robot_1_elbow_joint">
      <hardwareInterface>hardware_interface/PositionJointInterface</hardwareInterface>
    </joint>
    <actuator name="robot_1_elbow_motor">
      <mechanicalReduction>1</mechanicalReduction>
    </actuator>
  </transmission>
  <transmission name="robot_1_wrist_1_trans">
    <type>transmission_interface/SimpleTransmission</type>
    <joint name="robot_1_wrist_1_joint">
      <hardwareInterface>hardware_interface/PositionJointInterface</hardwareInterface>
    </joint>
    <actuator name="robot_1_wrist_1_motor">
      <mechanicalReduction>1</mechanicalReduction>
    </actuator>
  </transmission>
  <transmission name="robot_1_wrist_2_trans">
    <type>transmission_interface/SimpleTransmission</type>
    <joint name="robot_1_wrist_2_joint">
      <hardwareInterface>hardware_interface/PositionJointInterface</hardwareInterface>
    </joint>
    <actuator name="robot_1_wrist_2_motor">
      <mechanicalReduction>1</mechanicalReduction>
    </actuator>
  </transmission>
  <transmission name="robot_1_wrist_3_trans">
    <type>transmission_interface/SimpleTransmission</type>
    <joint name="robot_1_wrist_3_joint">
      <hardwareInterface>hardware_interface/PositionJointInterface</hardwareInterface>
    </joint>
    <actuator name="robot_1_wrist_3_motor">
      <mechanicalReduction>1</mechanicalReduction>
    </actuator>
  </transmission>
  <gazebo reference="robot_1_shoulder_link">
    <selfCollide>true</selfCollide>
  </gazebo>
  <gazebo reference="robot_1_upper_arm_link">
    <selfCollide>true</selfCollide>
  </gazebo>
  <gazebo reference="robot_1_forearm_link">
    <selfCollide>true</selfCollide>
  </gazebo>
  <gazebo reference="robot_1_wrist_1_link">
    <selfCollide>true</selfCollide>
  </gazebo>
  <gazebo reference="robot_1_wrist_3_link">
    <selfCollide>true</selfCollide>
  </gazebo>
  <gazebo reference="robot_1_wrist_2_link">
    <selfCollide>true</selfCollide>
  </gazebo>
  <gazebo reference="robot_1_ee_link">
    <selfCollide>true</selfCollide>
  </gazebo>
  <!-- ROS base_link to UR 'Base' Coordinates transform -->
  <link name="robot_1_base"/>
  <joint name="robot_1_base_link-base_fixed_joint" type="fixed">
    <!-- NOTE: this rotation is only needed as long as base_link itself is
                 not corrected wrt the real robot (ie: rotated over 180
                 degrees)
      -->
    <origin rpy="0 0 -3.141592653589793" xyz="0 0 0"/>
    <parent link="robot_1_base_link"/>
    <child link="robot_1_base"/>
  </joint>
  <!-- Frame coincident with all-zeros TCP on UR controller -->
  <link name="robot_1_tool0"/>
  <joint name="robot_1_base_joint" type="fixed">
    <axis xyz="0 0 1"/>
    <parent link="robot_1_tool0"/>
    <child link="robot_1_conector"/>
    <origin rpy="0 0 0" xyz="0 0 0"/>
  </joint>
  <link name="robot_1_conector">
    <visual>
      <geometry>
        <mesh filename="package://laboratorio_robotica/mallas/RG2/visual/Quick_Changer_RobotSide.dae"/>
      </geometry>
      <origin rpy="1.5707963267948966 3.141592653589793 1.5707963267948966" xyz="0 0 0"/>
      <material name="CustomGrey">
        <color rgba="0.5 0.5 0.5 1.0"/>
      </material>
    </visual>
    <collision>
      <origin rpy="1.5707963267948966 3.141592653589793 1.5707963267948966" xyz="0 0 0"/>
      <geometry>
        <mesh filename="package://laboratorio_robotica/mallas/RG2/collision/Quick_Changer_RobotSide_collision.dae"/>
      </geometry>
    </collision>
    <inertial>
      <mass value="0.1"/>
      <inertia ixx="0.4" ixy="0.0" ixz="0.0" iyy="0.4" iyz="0.0" izz="0.2"/>
    </inertial>
  </link>
  <gazebo reference="robot_1_conector">
    <material>Gazebo/Grey</material>
  </gazebo>
  <joint name="robot_1_conector_joint" type="fixed">
    <parent link="robot_1_conector"/>
    <child link="robot_1_gripper"/>
    <origin rpy="0 0 0" xyz="0 0 0"/>
  </joint>
  <link name="robot_1_gripper">
    <visual>
      <geometry>
        <mesh filename="package://laboratorio_robotica/mallas/RG2/visual/RG2.stl" scale="0.001 0.001 0.001"/>
      </geometry>
      <material name="CustomGrey">
        <color rgba="0.5 0.5 0.5 1.0"/>
      </material>
      <origin rpy="3.141592653589793 -1.5707963267948966 1.5707963267948966" xyz="0 0 0"/>
    </visual>
    <collision>
      <origin rpy="3.141592653589793 -1.5707963267948966 1.5707963267948966" xyz="0 0 0"/>
      <geometry>
        <mesh filename="package://laboratorio_robotica/mallas/RG2/collision/RG2_collision.dae"/>
      </geometry>
    </collision>
    <inertial>
      <mass value="0.1"/>
      <inertia ixx="0.4" ixy="0.0" ixz="0.0" iyy="0.4" iyz="0.0" izz="0.2"/>
    </inertial>
  </link>
  <gazebo reference="robot_1_gripper">
    <material>Gazebo/Grey</material>
  </gazebo>
  <!-- measured from model -->
  <link name="robot_2_base_link">
    <visual>
      <origin rpy="0 0 3.141592653589793" xyz="0 0 0"/>
      <geometry>
        <mesh filename="package://ur_description/meshes/ur3/visual/base.dae"/>
      </geometry>
      <material name="LightGrey">
        <color rgba="0.7 0.7 0.7 1.0"/>
      </material>
    </visual>
    <collision>
      <origin rpy="0 0 3.141592653589793" xyz="0 0 0"/>
      <geometry>
        <mesh filename="package://ur_description/meshes/ur3/collision/base.stl"/>
      </geometry>
    </collision>
    <inertial>
      <mass value="2.0"/>
      <origin rpy="0 0 0" xyz="0.0 0.0 0.0"/>
      <inertia ixx="0.0030531654454" ixy="0.0" ixz="0.0" iyy="0.0030531654454" iyz="0.0" izz="0.005625"/>
    </inertial>
  </link>
  <joint name="robot_2_shoulder_pan_joint" type="revolute">
    <parent link="robot_2_base_link"/>
    <child link="robot_2_shoulder_link"/>
    <origin rpy="0 0 3.141592528371097" xyz="0 0 0.151982148052407"/>
    <axis xyz="0 0 1"/>
    <limit effort="330.0" lower="-3.141592653589793" upper="3.141592653589793" velocity="2.16"/>
    <dynamics damping="0.0" friction="0.0"/>
  </joint>
  <link name="robot_2_shoulder_link">
    <visual>
      <origin rpy="0 0 3.141592653589793" xyz="0 0 0"/>
      <geometry>
        <mesh filename="package://ur_description/meshes/ur3/visual/shoulder.dae"/>
      </geometry>
      <material name="LightGrey">
        <color rgba="0.7 0.7 0.7 1.0"/>
      </material>
    </visual>
    <collision>
      <origin rpy="0 0 3.141592653589793" xyz="0 0 0"/>
      <geometry>
        <mesh filename="package://ur_description/meshes/ur3/collision/shoulder.stl"/>
      </geometry>
    </collision>
    <inertial>
      <mass value="2.0"/>
      <origin rpy="0 0 0" xyz="0.0 0.0 0.0"/>
      <inertia ixx="0.008093163429399999" ixy="0.0" ixz="0.0" iyy="0.008093163429399999" iyz="0.0" izz="0.005625"/>
    </inertial>
  </link>
  <joint name="robot_2_shoulder_lift_joint" type="revolute">
    <parent link="robot_2_shoulder_link"/>
    <child link="robot_2_upper_arm_link"/>
    <origin rpy="1.570529532239682 0 6.651065255205953e-06" xyz="-0.000117751414108642 0 0"/>
    <axis xyz="0 0 1"/>
    <limit effort="330.0" lower="-3.141592653589793" upper="3.141592653589793" velocity="2.16"/>
    <dynamics damping="0.0" friction="0.0"/>
  </joint>
  <link name="robot_2_upper_arm_link">
    <visual>
      <origin rpy="1.5707963267948966 0 -1.5707963267948966" xyz="0 0 0.1198"/>
      <geometry>
        <mesh filename="package://ur_description/meshes/ur3/visual/upperarm.dae"/>
      </geometry>
      <material name="LightGrey">
        <color rgba="0.7 0.7 0.7 1.0"/>
      </material>
    </visual>
    <collision>
      <origin rpy="1.5707963267948966 0 -1.5707963267948966" xyz="0 0 0.1198"/>
      <geometry>
        <mesh filename="package://ur_description/meshes/ur3/collision/upperarm.stl"/>
      </geometry>
    </collision>
    <inertial>
      <mass value="3.42"/>
      <origin rpy="0 1.5707963267948966 0" xyz="-0.12191505529225105 0.0 0.12"/>
      <inertia ixx="0.021753506304474392" ixy="0.0" ixz="0.0" iyy="0.021753506304474392" iyz="0.0" izz="0.00961875"/>
    </inertial>
  </link>
  <joint name="robot_2_elbow_joint" type="revolute">
    <parent link="robot_2_upper_arm_link"/>
    <child link="robot_2_forearm_link"/>
    <origin rpy="3.140422330317566 3.140175127557685 3.141557960492696" xyz="-0.2438301105845021 0 0"/>
    <axis xyz="0 0 1"/>
    <limit effort="150.0" lower="-3.141592653589793" upper="3.141592653589793" velocity="3.15"/>
    <dynamics damping="0.0" friction="0.0"/>
  </joint>
  <link name="robot_2_forearm_link">
    <visual>
      <origin rpy="1.5707963267948966 0 -1.5707963267948966" xyz="0 0 0.0275"/>
      <geometry>
        <mesh filename="package://ur_description/meshes/ur3/visual/forearm.dae"/>
      </geometry>
      <material name="LightGrey">
        <color rgba="0.7 0.7 0.7 1.0"/>
      </material>
    </visual>
    <collision>
      <origin rpy="1.5707963267948966 0 -1.5707963267948966" xyz="0 0 0.0275"/>
      <geometry>
        <mesh filename="package://ur_description/meshes/ur3/collision/forearm.stl"/>
      </geometry>
    </collision>
    <inertial>
      <mass value="1.26"/>
      <origin rpy="0 1.5707963267948966 0" xyz="-0.12191505529225105 0.0 0.0275"/>
      <inertia ixx="0.006536231541073107" ixy="0.0" ixz="0.0" iyy="0.006536231541073107" iyz="0.0" izz="0.00354375"/>
    </inertial>
  </link>
  <joint name="robot_2_wrist_1_joint" type="revolute">
    <parent link="robot_2_forearm_link"/>
    <child link="robot_2_wrist_1_link"/>
    <origin rpy="0.006363349347924476 0.00401697960892016 4.539196023121239e-06" xyz="-0.2130137298406746 -0.0008374574461011085 0.131604615239527"/>
    <axis xyz="0 0 1"/>
    <limit effort="54.0" lower="-3.141592653589793" upper="3.141592653589793" velocity="3.2"/>
    <dynamics damping="0.0" friction="0.0"/>
  </joint>
  <link name="robot_2_wrist_1_link">
    <visual>
      <origin rpy="1.5707963267948966 0 0" xyz="0 0 -0.085"/>
      <geometry>
        <mesh filename="package://ur_description/meshes/ur3/visual/wrist1.dae"/>
      </geometry>
      <material name="LightGrey">
        <color rgba="0.7 0.7 0.7 1.0"/>
      </material>
    </visual>
    <collision>
      <origin rpy="1.5707963267948966 0 0" xyz="0 0 -0.085"/>
      <geometry>
        <mesh filename="package://ur_description/meshes/ur3/collision/wrist1.stl"/>
      </geometry>
    </collision>
    <inertial>
      <mass value="0.8"/>
      <origin rpy="0 0 0" xyz="0.0 0.0 0.0"/>
      <inertia ixx="0.0016115361059691796" ixy="0.0" ixz="0.0" iyy="0.0016115361059691796" iyz="0.0" izz="0.00225"/>
    </inertial>
  </link>
  <joint name="robot_2_wrist_2_joint" type="revolute">
    <parent link="robot_2_wrist_1_link"/>
    <child link="robot_2_wrist_2_link"/>
    <origin rpy="1.571802682556826 0 -2.655106245398608e-06" xyz="6.007850950088259e-06 -0.08542863254646067 -8.597162561949335e-05"/>
    <axis xyz="0 0 1"/>
    <limit effort="54.0" lower="-3.141592653589793" upper="3.141592653589793" velocity="3.2"/>
    <dynamics damping="0.0" friction="0.0"/>
  </joint>
  <link name="robot_2_wrist_2_link">
    <visual>
      <origin rpy="0 0 0" xyz="0 0 -0.085"/>
      <geometry>
        <mesh filename="package://ur_description/meshes/ur3/visual/wrist2.dae"/>
      </geometry>
      <material name="LightGrey">
        <color rgba="0.7 0.7 0.7 1.0"/>
      </material>
    </visual>
    <collision>
      <origin rpy="0 0 0" xyz="0 0 -0.085"/>
      <geometry>
        <mesh filename="package://ur_description/meshes/ur3/collision/wrist2.stl"/>
      </geometry>
    </collision>
    <inertial>
      <mass value="0.8"/>
      <origin rpy="0 0 0" xyz="0.0 0.0 0.0"/>
      <inertia ixx="0.001691598927723632" ixy="0.0" ixz="0.0" iyy="0.001691598927723632" iyz="0.0" izz="0.00225"/>
    </inertial>
  </link>
  <joint name="robot_2_wrist_3_joint" type="revolute">
    <parent link="robot_2_wrist_2_link"/>
    <child link="robot_2_wrist_3_link"/>
    <origin rpy="1.570313920297103 3.141592653589793 3.141592540005369" xyz="-5.693288443582482e-05 0.09218998896546257 -4.447305315826958e-05"/>
    <axis xyz="0 0 1"/>
    <limit effort="54.0" lower="-3.141592653589793" upper="3.141592653589793" velocity="3.2"/>
    <dynamics damping="0.0" friction="0.0"/>
  </joint>
  <link name="robot_2_wrist_3_link">
    <visual>
      <origin rpy="1.5707963267948966 0 0" xyz="0 0 -0.082"/>
      <geometry>
        <mesh filename="package://ur_description/meshes/ur3/visual/wrist3.dae"/>
      </geometry>
      <material name="LightGrey">
        <color rgba="0.7 0.7 0.7 1.0"/>
      </material>
    </visual>
    <collision>
      <origin rpy="1.5707963267948966 0 0" xyz="0 0 -0.082"/>
      <geometry>
        <mesh filename="package://ur_description/meshes/ur3/collision/wrist3.stl"/>
      </geometry>
    </collision>
    <inertial>
      <mass value="0.35"/>
      <origin rpy="0 0 0" xyz="0.0 0.0 -0.01525"/>
      <inertia ixx="0.00020431970993874997" ixy="0.0" ixz="0.0" iyy="0.00020431970993874997" iyz="0.0" izz="0.000354375"/>
    </inertial>
  </link>
  <joint name="robot_2_ee_fixed_joint" type="fixed">
    <parent link="robot_2_wrist_3_link"/>
    <child link="robot_2_ee_link"/>
    <origin rpy="0.0 -1.5707963267948966 1.5707963267948966" xyz="0.0 0.0 0.0"/>
  </joint>
  <link name="robot_2_ee_link">
    <collision>
      <geometry>
        <box size="0.01 0.01 0.01"/>
      </geometry>
      <origin rpy="0 0 0" xyz="-0.01 0 0"/>
    </collision>
  </link>
  <joint name="robot_2_wrist_3_passive_joint" type="fixed">
    <origin rpy="0 0 0" xyz="0 0 0"/>
    <parent link="robot_2_wrist_3_link"/>
    <child link="robot_2_tool0"/>
  </joint>
  <transmission name="robot_2_shoulder_pan_trans">
    <type>transmission_interface/SimpleTransmission</type>
    <joint name="robot_2_shoulder_pan_joint">
      <hardwareInterface>hardware_interface/PositionJointInterface</hardwareInterface>
    </joint>
    <actuator name="robot_2_shoulder_pan_motor">
      <mechanicalReduction>1</mechanicalReduction>
    </actuator>
  </transmission>
  <transmission name="robot_2_shoulder_lift_trans">
    <type>transmission_interface/SimpleTransmission</type>
    <joint name="robot_2_shoulder_lift_joint">
      <hardwareInterface>hardware_interface/PositionJointInterface</hardwareInterface>
    </joint>
    <actuator name="robot_2_shoulder_lift_motor">
      <mechanicalReduction>1</mechanicalReduction>
    </actuator>
  </transmission>
  <transmission name="robot_2_elbow_trans">
    <type>transmission_interface/SimpleTransmission</type>
    <joint name="robot_2_elbow_joint">
      <hardwareInterface>hardware_interface/PositionJointInterface</hardwareInterface>
    </joint>
    <actuator name="robot_2_elbow_motor">
      <mechanicalReduction>1</mechanicalReduction>
    </actuator>
  </transmission>
  <transmission name="robot_2_wrist_1_trans">
    <type>transmission_interface/SimpleTransmission</type>
    <joint name="robot_2_wrist_1_joint">
      <hardwareInterface>hardware_interface/PositionJointInterface</hardwareInterface>
    </joint>
    <actuator name="robot_2_wrist_1_motor">
      <mechanicalReduction>1</mechanicalReduction>
    </actuator>
  </transmission>
  <transmission name="robot_2_wrist_2_trans">
    <type>transmission_interface/SimpleTransmission</type>
    <joint name="robot_2_wrist_2_joint">
      <hardwareInterface>hardware_interface/PositionJointInterface</hardwareInterface>
    </joint>
    <actuator name="robot_2_wrist_2_motor">
      <mechanicalReduction>1</mechanicalReduction>
    </actuator>
  </transmission>
  <transmission name="robot_2_wrist_3_trans">
    <type>transmission_interface/SimpleTransmission</type>
    <joint name="robot_2_wrist_3_joint">
      <hardwareInterface>hardware_interface/PositionJointInterface</hardwareInterface>
    </joint>
    <actuator name="robot_2_wrist_3_motor">
      <mechanicalReduction>1</mechanicalReduction>
    </actuator>
  </transmission>
  <gazebo reference="robot_2_shoulder_link">
    <selfCollide>true</selfCollide>
  </gazebo>
  <gazebo reference="robot_2_upper_arm_link">
    <selfCollide>true</selfCollide>
  </gazebo>
  <gazebo reference="robot_2_forearm_link">
    <selfCollide>true</selfCollide>
  </gazebo>
  <gazebo reference="robot_2_wrist_1_link">
    <selfCollide>true</selfCollide>
  </gazebo>
  <gazebo reference="robot_2_wrist_3_link">
    <selfCollide>true</selfCollide>
  </gazebo>
  <gazebo reference="robot_2_wrist_2_link">
    <selfCollide>true</selfCollide>
  </gazebo>
  <gazebo reference="robot_2_ee_link">
    <selfCollide>true</selfCollide>
  </gazebo>
  <!-- ROS base_link to UR 'Base' Coordinates transform -->
  <link name="robot_2_base"/>
  <joint name="robot_2_base_link-base_fixed_joint" type="fixed">
    <!-- NOTE: this rotation is only needed as long as base_link itself is
                 not corrected wrt the real robot (ie: rotated over 180
                 degrees)
      -->
    <origin rpy="0 0 -3.141592653589793" xyz="0 0 0"/>
    <parent link="robot_2_base_link"/>
    <child link="robot_2_base"/>
  </joint>
  <!-- Frame coincident with all-zeros TCP on UR controller -->
  <link name="robot_2_tool0"/>
  <joint name="robot_2_base_joint" type="fixed">
    <axis xyz="0 0 1"/>
    <parent link="robot_2_tool0"/>
    <child link="robot_2_conector"/>
    <origin rpy="0 0 0" xyz="0 0 0"/>
  </joint>
  <link name="robot_2_conector">
    <visual>
      <geometry>
        <mesh filename="package://laboratorio_robotica/mallas/RG2/visual/Quick_Changer_RobotSide.dae"/>
      </geometry>
      <origin rpy="1.5707963267948966 3.141592653589793 1.5707963267948966" xyz="0 0 0"/>
      <material name="CustomGrey">
        <color rgba="0.5 0.5 0.5 1.0"/>
      </material>
    </visual>
    <collision>
      <origin rpy="1.5707963267948966 3.141592653589793 1.5707963267948966" xyz="0 0 0"/>
      <geometry>
        <mesh filename="package://laboratorio_robotica/mallas/RG2/collision/Quick_Changer_RobotSide_collision.dae"/>
      </geometry>
    </collision>
    <inertial>
      <mass value="0.1"/>
      <inertia ixx="0.4" ixy="0.0" ixz="0.0" iyy="0.4" iyz="0.0" izz="0.2"/>
    </inertial>
  </link>
  <gazebo reference="robot_2_conector">
    <material>Gazebo/Grey</material>
  </gazebo>
  <joint name="robot_2_conector_joint" type="fixed">
    <parent link="robot_2_conector"/>
    <child link="robot_2_gripper"/>
    <origin rpy="0 0 0" xyz="0 0 0"/>
  </joint>
  <link name="robot_2_gripper">
    <visual>
      <geometry>
        <mesh filename="package://laboratorio_robotica/mallas/RG2/visual/RG2.stl" scale="0.001 0.001 0.001"/>
      </geometry>
      <material name="CustomGrey">
        <color rgba="0.5 0.5 0.5 1.0"/>
      </material>
      <origin rpy="3.141592653589793 -1.5707963267948966 1.5707963267948966" xyz="0 0 0"/>
    </visual>
    <collision>
      <origin rpy="3.141592653589793 -1.5707963267948966 1.5707963267948966" xyz="0 0 0"/>
      <geometry>
        <mesh filename="package://laboratorio_robotica/mallas/RG2/collision/RG2_collision.dae"/>
      </geometry>
    </collision>
    <inertial>
      <mass value="0.1"/>
      <inertia ixx="0.4" ixy="0.0" ixz="0.0" iyy="0.4" iyz="0.0" izz="0.2"/>
    </inertial>
  </link>
  <gazebo reference="robot_2_gripper">
    <material>Gazebo/Grey</material>
  </gazebo>
  <!-- Suelo común para los 2 robots(Es necesario para luego juntar el suelo común con el world) -->
  <link name="suelo_sistema">
    <visual>
      <origin rpy="0 0 0" xyz="0.45699999999999996 0.272 0.25"/>
      <geometry>
        <box size="1.2 0.83 0.5"/>
      </geometry>
      <material name="LightGrey">
        <color rgba="0.7 0.7 0.7 1.0"/>
      </material>
    </visual>
    <collision>
      <origin rpy="0 0 0" xyz="0.45699999999999996 0.272 0.25"/>
      <geometry>
        <box size="1.2 0.83 0.5"/>
      </geometry>
    </collision>
    <inertial>
      <mass value="0.1"/>
      <inertia ixx="0.4" ixy="0.0" ixz="0.0" iyy="0.4" iyz="0.0" izz="0.2"/>
    </inertial>
  </link>
  <gazebo reference="suelo_sistema">
    <material>PR2/Grey3</material>
  </gazebo>
  <!-- Juntas al suelo de los 2 robots -->
  <joint name="junta_suelo_sistema_robot_1" type="fixed">
    <parent link="suelo_sistema"/>
    <child link="robot_1_base_link"/>
    <origin rpy="0.0 0.0 -0.769" xyz="0.0 0.0 0.5"/>
  </joint>
  <joint name="junta_suelo_sistema_robot_2" type="fixed">
    <parent link="suelo_sistema"/>
    <child link="robot_2_base_link"/>
    <origin rpy="0.0 0.0 0.9562" xyz="0.902 0.01 0.5"/>
  </joint>
  <!-- Junta  con el suelo de gazebo -->
  <link name="world"/>
  <joint name="world_joint" type="fixed">
    <parent link="world"/>
    <child link="suelo_sistema"/>
    <origin rpy="0.0 0.0 0.0" xyz="0.0 0.0 0.0"/>
  </joint>
</robot>

